ERROR 2025-05-18 14:08:05,183 Internal Server Error: /api/invoice/saleinvoice
Traceback (most recent call last):
  File "C:\educure\api\venv\Lib\site-packages\django\core\handlers\exception.py", line 55, in inner
    response = get_response(request)
  File "C:\educure\api\venv\Lib\site-packages\django\core\handlers\base.py", line 197, in _get_response
    response = wrapped_callback(request, *callback_args, **callback_kwargs)
  File "C:\educure\api\venv\Lib\site-packages\django\views\decorators\csrf.py", line 65, in _view_wrapper
    return view_func(request, *args, **kwargs)
  File "C:\educure\api\venv\Lib\site-packages\django\views\generic\base.py", line 104, in view
    return self.dispatch(request, *args, **kwargs)
           ~~~~~~~~~~~~~^^^^^^^^^^^^^^^^^^^^^^^^^^
  File "C:\educure\api\venv\Lib\site-packages\rest_framework\views.py", line 515, in dispatch
    response = self.handle_exception(exc)
  File "C:\educure\api\venv\Lib\site-packages\rest_framework\views.py", line 475, in handle_exception
    self.raise_uncaught_exception(exc)
    ~~~~~~~~~~~~~~~~~~~~~~~~~~~~~^^^^^
  File "C:\educure\api\venv\Lib\site-packages\rest_framework\views.py", line 486, in raise_uncaught_exception
    raise exc
  File "C:\educure\api\venv\Lib\site-packages\rest_framework\views.py", line 512, in dispatch
    response = handler(request, *args, **kwargs)
  File "C:\educure\api\venv\Lib\site-packages\rest_framework\generics.py", line 246, in post
    return self.create(request, *args, **kwargs)
           ~~~~~~~~~~~^^^^^^^^^^^^^^^^^^^^^^^^^^
  File "C:\educure\api\venv\Lib\site-packages\rest_framework\mixins.py", line 19, in create
    self.perform_create(serializer)
    ~~~~~~~~~~~~~~~~~~~^^^^^^^^^^^^
  File "C:\educure\api\Finacc\invoice\views.py", line 645, in perform_create
    return serializer.save(createdby = self.request.user)
           ~~~~~~~~~~~~~~~^^^^^^^^^^^^^^^^^^^^^^^^^^^^^^^
  File "C:\educure\api\venv\Lib\site-packages\rest_framework\serializers.py", line 210, in save
    self.instance = self.create(validated_data)
                    ~~~~~~~~~~~^^^^^^^^^^^^^^^^
  File "C:\educure\api\Finacc\invoice\serializers.py", line 2299, in create
    stk.createtransaction()
    ~~~~~~~~~~~~~~~~~~~~~^^
  File "C:\educure\api\Finacc\invoice\serializers.py", line 1077, in createtransaction
    StockTransactions.objects.create(accounthead=roundoffid.accounthead, account=roundoffid, transactiontype=self.transactiontype, transactionid=id, desc=self.description + ' ' + str(self.order.billno), drcr=self.debit, debitamount=abs(roundOff), entity=self.order.entity, createdby=self.order.createdby, entry=entryid, entrydatetime=self.order.sorderdate, voucherno=self.order.billno)
                                                 ^^^^^^^^^^^^^^^^^^^^^^
AttributeError: 'NoneType' object has no attribute 'accounthead'
ERROR 2025-05-18 14:08:05,204 "POST /api/invoice/saleinvoice HTTP/1.1" 500 159024
ERROR 2025-05-18 14:09:55,265 Internal Server Error: /api/invoice/saleinvoice
Traceback (most recent call last):
  File "C:\educure\api\venv\Lib\site-packages\django\core\handlers\exception.py", line 55, in inner
    response = get_response(request)
  File "C:\educure\api\venv\Lib\site-packages\django\core\handlers\base.py", line 197, in _get_response
    response = wrapped_callback(request, *callback_args, **callback_kwargs)
  File "C:\educure\api\venv\Lib\site-packages\django\views\decorators\csrf.py", line 65, in _view_wrapper
    return view_func(request, *args, **kwargs)
  File "C:\educure\api\venv\Lib\site-packages\django\views\generic\base.py", line 104, in view
    return self.dispatch(request, *args, **kwargs)
           ~~~~~~~~~~~~~^^^^^^^^^^^^^^^^^^^^^^^^^^
  File "C:\educure\api\venv\Lib\site-packages\rest_framework\views.py", line 515, in dispatch
    response = self.handle_exception(exc)
  File "C:\educure\api\venv\Lib\site-packages\rest_framework\views.py", line 475, in handle_exception
    self.raise_uncaught_exception(exc)
    ~~~~~~~~~~~~~~~~~~~~~~~~~~~~~^^^^^
  File "C:\educure\api\venv\Lib\site-packages\rest_framework\views.py", line 486, in raise_uncaught_exception
    raise exc
  File "C:\educure\api\venv\Lib\site-packages\rest_framework\views.py", line 512, in dispatch
    response = handler(request, *args, **kwargs)
  File "C:\educure\api\venv\Lib\site-packages\rest_framework\generics.py", line 246, in post
    return self.create(request, *args, **kwargs)
           ~~~~~~~~~~~^^^^^^^^^^^^^^^^^^^^^^^^^^
  File "C:\educure\api\venv\Lib\site-packages\rest_framework\mixins.py", line 19, in create
    self.perform_create(serializer)
    ~~~~~~~~~~~~~~~~~~~^^^^^^^^^^^^
  File "C:\educure\api\Finacc\invoice\views.py", line 645, in perform_create
    return serializer.save(createdby = self.request.user)
           ~~~~~~~~~~~~~~~^^^^^^^^^^^^^^^^^^^^^^^^^^^^^^^
  File "C:\educure\api\venv\Lib\site-packages\rest_framework\serializers.py", line 210, in save
    self.instance = self.create(validated_data)
                    ~~~~~~~~~~~^^^^^^^^^^^^^^^^
  File "C:\educure\api\Finacc\invoice\serializers.py", line 2299, in create
    stk.createtransaction()
    ~~~~~~~~~~~~~~~~~~~~~^^
  File "C:\educure\api\Finacc\invoice\serializers.py", line 1077, in createtransaction
    StockTransactions.objects.create(accounthead=roundoffid.accounthead, account=roundoffid, transactiontype=self.transactiontype, transactionid=id, desc=self.description + ' ' + str(self.order.billno), drcr=self.debit, debitamount=abs(roundOff), entity=self.order.entity, createdby=self.order.createdby, entry=entryid, entrydatetime=self.order.sorderdate, voucherno=self.order.billno)
                                                 ^^^^^^^^^^^^^^^^^^^^^^
AttributeError: 'NoneType' object has no attribute 'accounthead'
ERROR 2025-05-18 14:09:55,310 "POST /api/invoice/saleinvoice HTTP/1.1" 500 159024
ERROR 2025-05-18 14:14:31,423 Internal Server Error: /api/invoice/saleinvoice
Traceback (most recent call last):
  File "C:\educure\api\venv\Lib\site-packages\django\core\handlers\base.py", line 197, in _get_response
    response = wrapped_callback(request, *callback_args, **callback_kwargs)
  File "C:\educure\api\venv\Lib\site-packages\django\views\decorators\csrf.py", line 65, in _view_wrapper
    return view_func(request, *args, **kwargs)
  File "C:\educure\api\venv\Lib\site-packages\django\views\generic\base.py", line 104, in view
    return self.dispatch(request, *args, **kwargs)
           ~~~~~~~~~~~~~^^^^^^^^^^^^^^^^^^^^^^^^^^
  File "C:\educure\api\venv\Lib\site-packages\rest_framework\views.py", line 515, in dispatch
    response = self.handle_exception(exc)
  File "C:\educure\api\venv\Lib\site-packages\rest_framework\views.py", line 475, in handle_exception
    self.raise_uncaught_exception(exc)
    ~~~~~~~~~~~~~~~~~~~~~~~~~~~~~^^^^^
  File "C:\educure\api\venv\Lib\site-packages\rest_framework\views.py", line 486, in raise_uncaught_exception
    raise exc
  File "C:\educure\api\venv\Lib\site-packages\rest_framework\views.py", line 512, in dispatch
    response = handler(request, *args, **kwargs)
  File "C:\educure\api\venv\Lib\site-packages\rest_framework\generics.py", line 246, in post
    return self.create(request, *args, **kwargs)
           ~~~~~~~~~~~^^^^^^^^^^^^^^^^^^^^^^^^^^
  File "C:\educure\api\venv\Lib\site-packages\rest_framework\mixins.py", line 19, in create
    self.perform_create(serializer)
    ~~~~~~~~~~~~~~~~~~~^^^^^^^^^^^^
  File "C:\educure\api\Finacc\invoice\views.py", line 645, in perform_create
    return serializer.save(createdby = self.request.user)
           ~~~~~~~~~~~~~~~^^^^^^^^^^^^^^^^^^^^^^^^^^^^^^^
  File "C:\educure\api\venv\Lib\site-packages\rest_framework\serializers.py", line 210, in save
    self.instance = self.create(validated_data)
                    ~~~~~~~~~~~^^^^^^^^^^^^^^^^
  File "C:\educure\api\Finacc\invoice\serializers.py", line 2299, in create
    stk.createtransaction()
    ~~~~~~~~~~~~~~~~~~~~~^^
  File "C:\educure\api\Finacc\invoice\serializers.py", line 1077, in createtransaction
    StockTransactions.objects.create(accounthead=roundoffid.accounthead, account=roundoffid, transactiontype=self.transactiontype, transactionid=id, desc=self.description + ' ' + str(self.order.billno), drcr=self.debit, debitamount=abs(roundOff), entity=self.order.entity, createdby=self.order.createdby, entry=entryid, entrydatetime=self.order.sorderdate, voucherno=self.order.billno)
                                                 ^^^^^^^^^^^^^^^^^^^^^^
AttributeError: 'NoneType' object has no attribute 'accounthead'

During handling of the above exception, another exception occurred:

Traceback (most recent call last):
  File "C:\educure\api\venv\Lib\site-packages\django\core\handlers\exception.py", line 55, in inner
    response = get_response(request)
  File "C:\educure\api\venv\Lib\site-packages\django\core\handlers\base.py", line 199, in _get_response
    response = self.process_exception_by_middleware(e, request)
  File "C:\educure\api\venv\Lib\site-packages\django\core\handlers\base.py", line 362, in process_exception_by_middleware
    response = middleware_method(request, exception)
  File "C:\educure\api\Finacc\errorlogger\middleware.py", line 20, in process_exception
    request_data=request.body.decode('utf-8') if request.body else None
                                                 ^^^^^^^^^^^^
  File "C:\educure\api\venv\Lib\site-packages\django\http\request.py", line 363, in body
    raise RawPostDataException(
        "You cannot access body after reading from request's data stream"
    )
django.http.request.RawPostDataException: You cannot access body after reading from request's data stream
ERROR 2025-05-18 14:14:31,440 "POST /api/invoice/saleinvoice HTTP/1.1" 500 176851
ERROR 2025-05-18 14:24:52,852 Internal Server Error: /api/invoice/saleinvoice
Traceback (most recent call last):
  File "C:\educure\api\venv\Lib\site-packages\django\core\handlers\base.py", line 197, in _get_response
    response = wrapped_callback(request, *callback_args, **callback_kwargs)
  File "C:\educure\api\venv\Lib\site-packages\django\views\decorators\csrf.py", line 65, in _view_wrapper
    return view_func(request, *args, **kwargs)
  File "C:\educure\api\venv\Lib\site-packages\django\views\generic\base.py", line 104, in view
    return self.dispatch(request, *args, **kwargs)
           ~~~~~~~~~~~~~^^^^^^^^^^^^^^^^^^^^^^^^^^
  File "C:\educure\api\venv\Lib\site-packages\rest_framework\views.py", line 515, in dispatch
    response = self.handle_exception(exc)
  File "C:\educure\api\venv\Lib\site-packages\rest_framework\views.py", line 475, in handle_exception
    self.raise_uncaught_exception(exc)
    ~~~~~~~~~~~~~~~~~~~~~~~~~~~~~^^^^^
  File "C:\educure\api\venv\Lib\site-packages\rest_framework\views.py", line 486, in raise_uncaught_exception
    raise exc
  File "C:\educure\api\venv\Lib\site-packages\rest_framework\views.py", line 512, in dispatch
    response = handler(request, *args, **kwargs)
  File "C:\educure\api\venv\Lib\site-packages\rest_framework\generics.py", line 246, in post
    return self.create(request, *args, **kwargs)
           ~~~~~~~~~~~^^^^^^^^^^^^^^^^^^^^^^^^^^
  File "C:\educure\api\venv\Lib\site-packages\rest_framework\mixins.py", line 19, in create
    self.perform_create(serializer)
    ~~~~~~~~~~~~~~~~~~~^^^^^^^^^^^^
  File "C:\educure\api\Finacc\invoice\views.py", line 645, in perform_create
    return serializer.save(createdby = self.request.user)
           ~~~~~~~~~~~~~~~^^^^^^^^^^^^^^^^^^^^^^^^^^^^^^^
  File "C:\educure\api\venv\Lib\site-packages\rest_framework\serializers.py", line 210, in save
    self.instance = self.create(validated_data)
                    ~~~~~~~~~~~^^^^^^^^^^^^^^^^
  File "C:\educure\api\Finacc\invoice\serializers.py", line 2299, in create
    stk.createtransaction()
    ~~~~~~~~~~~~~~~~~~~~~^^
  File "C:\educure\api\Finacc\invoice\serializers.py", line 1077, in createtransaction
    StockTransactions.objects.create(accounthead=roundoffid.accounthead, account=roundoffid, transactiontype=self.transactiontype, transactionid=id, desc=self.description + ' ' + str(self.order.billno), drcr=self.debit, debitamount=abs(roundOff), entity=self.order.entity, createdby=self.order.createdby, entry=entryid, entrydatetime=self.order.sorderdate, voucherno=self.order.billno)
                                                 ^^^^^^^^^^^^^^^^^^^^^^
AttributeError: 'NoneType' object has no attribute 'accounthead'

During handling of the above exception, another exception occurred:

Traceback (most recent call last):
  File "C:\educure\api\venv\Lib\site-packages\django\core\handlers\exception.py", line 55, in inner
    response = get_response(request)
  File "C:\educure\api\venv\Lib\site-packages\django\core\handlers\base.py", line 199, in _get_response
    response = self.process_exception_by_middleware(e, request)
  File "C:\educure\api\venv\Lib\site-packages\django\core\handlers\base.py", line 362, in process_exception_by_middleware
    response = middleware_method(request, exception)
  File "C:\educure\api\Finacc\errorlogger\middleware.py", line 20, in process_exception
    request_data=request.body.decode('utf-8') if request.body else None
                                                 ^^^^^^^^^^^^
  File "C:\educure\api\venv\Lib\site-packages\django\http\request.py", line 363, in body
    raise RawPostDataException(
        "You cannot access body after reading from request's data stream"
    )
django.http.request.RawPostDataException: You cannot access body after reading from request's data stream
ERROR 2025-05-18 14:24:52,876 "POST /api/invoice/saleinvoice HTTP/1.1" 500 176962
ERROR 2025-05-18 17:40:44,891 Internal Server Error: /api/auth/login
Traceback (most recent call last):
  File "C:\educure\api\venv\Lib\site-packages\django\core\handlers\exception.py", line 55, in inner
    response = get_response(request)
  File "C:\educure\api\Finacc\auditlogger\middleware.py", line 10, in __call__
    user = request.user if request.user.is_authenticated else None
                           ^^^^^^^^^^^^
AttributeError: 'WSGIRequest' object has no attribute 'user'
ERROR 2025-05-18 17:40:44,894 "OPTIONS /api/auth/login HTTP/1.1" 500 70427
ERROR 2025-05-18 17:41:18,433 Internal Server Error: /api/auth/login
Traceback (most recent call last):
  File "C:\educure\api\venv\Lib\site-packages\django\core\handlers\exception.py", line 55, in inner
    response = get_response(request)
  File "C:\educure\api\Finacc\auditlogger\middleware.py", line 10, in __call__
    user = request.user if request.user.is_authenticated else None
                           ^^^^^^^^^^^^
AttributeError: 'WSGIRequest' object has no attribute 'user'
ERROR 2025-05-18 17:41:18,434 "OPTIONS /api/auth/login HTTP/1.1" 500 70427
ERROR 2025-05-18 17:41:21,925 Internal Server Error: /admin/errorlogger/errorlog/
Traceback (most recent call last):
  File "C:\educure\api\venv\Lib\site-packages\django\core\handlers\exception.py", line 55, in inner
    response = get_response(request)
  File "C:\educure\api\Finacc\auditlogger\middleware.py", line 10, in __call__
    user = request.user if request.user.is_authenticated else None
                           ^^^^^^^^^^^^
AttributeError: 'WSGIRequest' object has no attribute 'user'
ERROR 2025-05-18 17:41:21,926 "GET /admin/errorlogger/errorlog/ HTTP/1.1" 500 71809
ERROR 2025-05-18 17:41:29,012 Internal Server Error: /admin
Traceback (most recent call last):
  File "C:\educure\api\venv\Lib\site-packages\django\core\handlers\exception.py", line 55, in inner
    response = get_response(request)
  File "C:\educure\api\Finacc\auditlogger\middleware.py", line 10, in __call__
    user = request.user if request.user.is_authenticated else None
                           ^^^^^^^^^^^^
AttributeError: 'WSGIRequest' object has no attribute 'user'
ERROR 2025-05-18 17:41:29,016 "GET /admin HTTP/1.1" 500 71184
ERROR 2025-05-18 17:41:33,881 Internal Server Error: /
Traceback (most recent call last):
  File "C:\educure\api\venv\Lib\site-packages\django\core\handlers\exception.py", line 55, in inner
    response = get_response(request)
  File "C:\educure\api\Finacc\auditlogger\middleware.py", line 10, in __call__
    user = request.user if request.user.is_authenticated else None
                           ^^^^^^^^^^^^
AttributeError: 'WSGIRequest' object has no attribute 'user'
ERROR 2025-05-18 17:41:33,884 "GET / HTTP/1.1" 500 71139
ERROR 2025-05-18 17:50:17,391 Internal Server Error: /api/invoice/saleinvoice/178
Traceback (most recent call last):
  File "C:\educure\api\venv\Lib\site-packages\django\core\handlers\exception.py", line 55, in inner
    response = get_response(request)
  File "C:\educure\api\venv\Lib\site-packages\django\core\handlers\base.py", line 197, in _get_response
    response = wrapped_callback(request, *callback_args, **callback_kwargs)
  File "C:\educure\api\venv\Lib\site-packages\django\views\decorators\csrf.py", line 65, in _view_wrapper
    return view_func(request, *args, **kwargs)
  File "C:\educure\api\venv\Lib\site-packages\django\views\generic\base.py", line 104, in view
    return self.dispatch(request, *args, **kwargs)
           ~~~~~~~~~~~~~^^^^^^^^^^^^^^^^^^^^^^^^^^
  File "C:\educure\api\venv\Lib\site-packages\rest_framework\views.py", line 515, in dispatch
    response = self.handle_exception(exc)
  File "C:\educure\api\venv\Lib\site-packages\rest_framework\views.py", line 475, in handle_exception
    self.raise_uncaught_exception(exc)
    ~~~~~~~~~~~~~~~~~~~~~~~~~~~~~^^^^^
  File "C:\educure\api\venv\Lib\site-packages\rest_framework\views.py", line 486, in raise_uncaught_exception
    raise exc
  File "C:\educure\api\venv\Lib\site-packages\rest_framework\views.py", line 512, in dispatch
    response = handler(request, *args, **kwargs)
  File "C:\educure\api\venv\Lib\site-packages\rest_framework\generics.py", line 289, in put
    return self.update(request, *args, **kwargs)
           ~~~~~~~~~~~^^^^^^^^^^^^^^^^^^^^^^^^^^
  File "C:\educure\api\venv\Lib\site-packages\rest_framework\mixins.py", line 68, in update
    self.perform_update(serializer)
    ~~~~~~~~~~~~~~~~~~~^^^^^^^^^^^^
  File "C:\educure\api\venv\Lib\site-packages\rest_framework\mixins.py", line 78, in perform_update
    serializer.save()
    ~~~~~~~~~~~~~~~^^
  File "C:\educure\api\venv\Lib\site-packages\rest_framework\serializers.py", line 205, in save
    self.instance = self.update(self.instance, validated_data)
                    ~~~~~~~~~~~^^^^^^^^^^^^^^^^^^^^^^^^^^^^^^^
  File "C:\educure\api\Finacc\invoice\serializers.py", line 2349, in update
    stk.createtransaction()
    ~~~~~~~~~~~~~~~~~~~~~^^
  File "C:\educure\api\Finacc\invoice\serializers.py", line 1077, in createtransaction
    StockTransactions.objects.create(accounthead=roundoffid.accounthead, account=roundoffid, transactiontype=self.transactiontype, transactionid=id, desc=self.description + ' ' + str(self.order.billno), drcr=self.debit, debitamount=abs(roundOff), entity=self.order.entity, createdby=self.order.createdby, entry=entryid, entrydatetime=self.order.sorderdate, voucherno=self.order.billno)
                                                 ^^^^^^^^^^^^^^^^^^^^^^
AttributeError: 'NoneType' object has no attribute 'accounthead'
ERROR 2025-05-18 17:50:17,405 "PUT /api/invoice/saleinvoice/178?entity=50 HTTP/1.1" 500 166410
